Workbook

Sheet Petunjuk
B1: KERTAS KERJA PENJAMINAN KUALITAS / QUALITY ASSURANCE APIP
B2: Penjaminan Kualitas Evidence Struktur dan Proses – KK 3.1 OPD | KAWAL SPIP
B4: A. IDENTITAS
B5: Nama OPD | C5: INSPEKTORAT KABUPATEN MAHAKAM ULU
B6: Tahun Penilaian | C6: 2026
B7: Tanggal Penjaminan Kualitas | C7: 28 Septembeer s.d 30 September 2026
B8: Pengendali Teknis | C8: Plt. Inspektur
B9: Ketua Tim | C9: Evolonia Dypuri Dew, S.IP, M.Si
B10: Anggota Tim | C10: Erik Firnandus Bang, ST
C11: Kresensia Eka Suba, ST
B13: B. PARAMETER PENILAIAN
B14: Ambang batas grade dinyatakan terpenuhi | C14: 1 | D14: dapat diubah
B15: Catatan ambang batas | C15: Default 100%: seluruh evidence yang relevan (selain N/A) pada suatu grade harus tersedia dan sesuai kriteria. Nilai ini adalah asumsi kertas kerja, bukan ketentuan Peraturan BPKP No. 5/2021; sesuaikan dengan kebijakan tim.
B17: C. CARA PENGISIAN (sheet 'KK Penjaminan Kualitas')
B18: Sel yang diisi | C18: Hanya sel berwarna kuning (kolom K s.d. P). Kolom lain terkunci secara konsep (berasal dari Pedoman KK 3.1) dan berisi rumus.
B19: K – Ketersediaan | C19: Ada / Tidak Ada / N/A. Gunakan N/A hanya untuk evidence bertanda 'jika ada' atau yang kejadiannya memang tidak terjadi pada periode penilaian; wajib diberi alasan di kolom Catatan. Item N/A dikeluarkan dari penyebut persentase.
B20: L – Identitas Dokumen | C20: Judul, nomor, dan tanggal dokumen yang benar-benar diperiksa (mis. 'Keputusan Kepala Dinas No. 800/12/2026 tgl 5 Feb 2026').
B21: M – Keabsahan | C21: Ya bila dokumen telah ditetapkan/ditandatangani pejabat berwenang (atau sah secara elektronik); Tidak bila masih draf/tanpa pengesahan.
B22: N – Periode | C22: Ya bila dokumen berlaku/dibuat untuk tahun penilaian; Tidak bila kedaluwarsa atau di luar periode.
B23: O – Substansi | C23: Sesuai / Sebagian / Tidak Sesuai – dibandingkan dengan Kriteria (kolom G) dan Fokus Pembuktian (kolom H).
B24: Q – Nilai (otomatis) | C24: 1 = Ada + Sah + Periode sesuai + Substansi Sesuai; 0,5 = Ada tetapi salah satu dari keabsahan/periode tidak terpenuhi atau substansi Sebagian; 0 = Tidak Ada atau Substansi Tidak Sesuai; kosong = belum dinilai atau N/A.
B25: R – Kesimpulan item (otomatis) | C25: Memenuhi / Memenuhi Sebagian / Tidak Memenuhi / N/A / Belum dinilai.
B26: % Pemenuhan | C26: Σ Nilai ÷ jumlah item yang dinilai (di luar N/A). Dihitung per grade, per parameter, per subunsur, per unsur, dan total OPD.
B27: Grade Indikatif | C27: Grade tertinggi yang dicapai secara berjenjang: E terpenuhi → Level 1; E+D → Level 2; E+D+C → Level 3; E s.d. B → Level 4; E s.d. A → Level 5. Ini indikasi dari kelengkapan dokumen, bukan simpulan akhir penilaian maturitas.
B29: D. CONTOH PENGISIAN SATU BARIS
B30: Evidence disarankan | C30: Pakta Integritas
B31: K – Ketersediaan | C31: Ada
B32: L – Identitas Dokumen | C32: Pakta Integritas Kepala Dinas & pejabat struktural, ditandatangani 6 Januari 2026
B33: M – Keabsahan | C33: Ya
B34: N – Periode | C34: Ya
B35: O – Hasil QA APIP dihitung otomatis berdasarkan penilaian pada KK Penjaminan Kualitas. | C35: Sebagian
B36: P – Catatan Penjamin Kualitas / QA APIP digunakan untuk mencatat alasan, koreksi, atau tindak lanjut. | C36: Pakta integritas pejabat fungsional belum lengkap (5 dari 12 pegawai)
B37: Q – Nilai (otomatis) | C37: 0,5 → Memenuhi Sebagian
B39: Sumber | C39: Daftar evidence diambil dari kolom (12) 'Nama Evidence yang Disarankan' pada Lampiran Pedoman KAWAL SPIP KK 3.1 OPD. Sesuai catatan pedoman, daftar ini adalah bukti yang disarankan, bukan daftar dokumen wajib Peraturan BPKP No. 5/2021.

Sheet KK Penjaminan Kualitas
A1: KERTAS KERJA PENJAMINAN KUALITAS / QUALITY ASSURANCE APIP – KK 3.1 OPD (STRUKTUR DAN PROSES)
A2: ="OPD: "&IF(Petunjuk!$C$5="","..........",Petunjuk!$C$5)&" | Tahun Penilaian: "&IF(Petunjuk!$C$6="","....",Petunjuk!$C$6)
A4: Kode Subunsur | B4: Uraian Subunsur | C4: No Par. | D4: Uraian Parameter | E4: Grade | F4: Tahapan Grade | G4: Kriteria | H4: Fokus yang Harus Dibuktikan | I4: No Item | J4: Nama Evidence yang Disarankan | K4: File Evidence (Tarikan Evidence Struktur & Proses) | L4: Ketersediaan (Ada/Tidak Ada/N/A) | M4: Identitas Dokumen yang Diperiksa (judul, nomor, tanggal) | N4: Keabsahan (Ya/Tidak) | O4: Periode Sesuai (Ya/Tidak) | P4: Substansi vs Kriteria (Sesuai/Sebagian/Tidak Sesuai) | Q4: Catatan Penjamin Kualitas / QA APIP | R4: Nilai | S4: Kesimpulan Item | T4: Kunci Par. | U4: % Grade
A5: 1 | B5: 2 | C5: 3 | D5: 4 | E5: 5 | F5: 6 | G5: 7 | H5: 8 | I5: 9 | J5: 10 | L5: 11 | M5: 12 | N5: 13 | O5: 14 | P5: 15 | Q5: 16 | R5: 17 | S5: 18 | T5: 19 | U5: 20
A6: 1.1 | B6: Penegakan Integritas dan Nilai Etika | C6: 1 | D6: K/L/D menegakkan integritas dan nilai etika dalam melaksanakan tugas dan fungsi organiasi | E6: A | F6: A – Perbaikan Berkelanjutan | G6: Penegakan integritas dan nilai etika telah diperbaiki secara berkelanjutan sehingga tercipta suasana kerja organisasi yang kondusif yang dapat mendorong kinerja para pegawai secara optimal | H6: Integritas dan nilai etika telah menjadi bagian dari perilaku organisasi dan diterapkan secara konsisten oleh individu/pegawai | I6: 1 | J6: Rekap monitoring/penerapan integritas selama 1 tahun | R6: =IF(OR(L6="",L6="N/A"),"",IF(L6="Tidak Ada",0,IF(P6="","",IF(P6="Tidak Sesuai",0,IF(AND(N6="Ya",O6="Ya",P6="Sesuai"),1,0.5))))) | S6: =IF(L6="N/A","N/A",IF(R6="","Belum dinilai",IF(R6=1,"Memenuhi",IF(R6=0,"Tidak Memenuhi","Memenuhi Sebagian")))) | T6: 1.1-1 | U6: =IF(COUNT(R6:R9)=0,"",SUM(R6:R9)/COUNT(R6:R9))
E7: A | I7: 2 | J7: Rekap pelanggaran dan tindak lanjut | R7: =IF(OR(L7="",L7="N/A"),"",IF(L7="Tidak Ada",0,IF(P7="","",IF(P7="Tidak Sesuai",0,IF(AND(N7="Ya",O7="Ya",P7="Sesuai"),1,0.5))))) | S7: =IF(L7="N/A","N/A",IF(R7="","Belum dinilai",IF(R7=1,"Memenuhi",IF(R7=0,"Tidak Memenuhi","Memenuhi Sebagian")))) | T7: 1.1-1
E8: A | I8: 3 | J8: Bukti perbaikan berkelanjutan | R8: =IF(OR(L8="",L8="N/A"),"",IF(L8="Tidak Ada",0,IF(P8="","",IF(P8="Tidak Sesuai",0,IF(AND(N8="Ya",O8="Ya",P8="Sesuai"),1,0.5))))) | S8: =IF(L8="N/A","N/A",IF(R8="","Belum dinilai",IF(R8=1,"Memenuhi",IF(R8=0,"Tidak Memenuhi","Memenuhi Sebagian")))) | T8: 1.1-1
E9: A | I9: 4 | J9: Bukti penerapan reward/punishment secara konsisten | R9: =IF(OR(L9="",L9="N/A"),"",IF(L9="Tidak Ada",0,IF(P9="","",IF(P9="Tidak Sesuai",0,IF(AND(N9="Ya",O9="Ya",P9="Sesuai"),1,0.5))))) | S9: =IF(L9="N/A","N/A",IF(R9="","Belum dinilai",IF(R9=1,"Memenuhi",IF(R9=0,"Tidak Memenuhi","Memenuhi Sebagian")))) | T9: 1.1-1
E10: B | F10: B – Evaluasi & Tindak Lanjut | G10: Kebijakan dan implementasi organisasi telah dievaluasi untuk meningkatkan integritas dan nilai etika para pegawai | H10: Penerapan integritas dan nilai etika telah dievaluasi dan hasilnya digunakan untuk melakukan perbaikan | I10: 1 | J10: Laporan hasil evaluasi/monitoring | Q10: Dokumen Level yang dipenuhi kurang relevan dengan kriteria | R10: =IF(OR(L10="",L10="N/A"),"",IF(L10="Tidak Ada",0,IF(P10="","",IF(P10="Tidak Sesuai",0,IF(AND(N10="Ya",O10="Ya",P10="Sesuai"),1,0.5))))) | S10: =IF(L10="N/A","N/A",IF(R10="","Belum dinilai",IF(R10=1,"Memenuhi",IF(R10=0,"Tidak Memenuhi","Memenuhi Sebagian")))) | T10: 1.1-1 | U10: =IF(COUNT(R10:R12)=0,"",SUM(R10:R12)/COUNT(R10:R12))
E11: B | I11: 2 | J11: Dokumen tindak lanjut hasil evaluasi | R11: =IF(OR(L11="",L11="N/A"),"",IF(L11="Tidak Ada",0,IF(P11="","",IF(P11="Tidak Sesuai",0,IF(AND(N11="Ya",O11="Ya",P11="Sesuai"),1,0.5))))) | S11: =IF(L11="N/A","N/A",IF(R11="","Belum dinilai",IF(R11=1,"Memenuhi",IF(R11=0,"Tidak Memenuhi","Memenuhi Sebagian")))) | T11: 1.1-1
E12: B | I12: 3 | J12: Bukti perbaikan kebijakan/SOP | R12: =IF(OR(L12="",L12="N/A"),"",IF(L12="Tidak Ada",0,IF(P12="","",IF(P12="Tidak Sesuai",0,IF(AND(N12="Ya",O12="Ya",P12="Sesuai"),1,0.5))))) | S12: =IF(L12="N/A","N/A",IF(R12="","Belum dinilai",IF(R12=1,"Memenuhi",IF(R12=0,"Tidak Memenuhi","Memenuhi Sebagian")))) | T12: 1.1-1
E13: C | F13: C – Implementasi | G13: Penegakan integritas dan nilai etika telah dilaksanakan oleh pegawai dalam pelaksanaan tugas dan fungsinya dalam organisasi | H13: Pimpinan memberikan keteladanan dan terdapat praktik nyata penegakan integritas | I13: 1 | J13: Pakta Integritas pimpinan | R13: =IF(OR(L13="",L13="N/A"),"",IF(L13="Tidak Ada",0,IF(P13="","",IF(P13="Tidak Sesuai",0,IF(AND(N13="Ya",O13="Ya",P13="Sesuai"),1,0.5))))) | S13: =IF(L13="N/A","N/A",IF(R13="","Belum dinilai",IF(R13=1,"Memenuhi",IF(R13=0,"Tidak Memenuhi","Memenuhi Sebagian")))) | T13: 1.1-1 | U13: =IF(COUNT(R13:R15)=0,"",SUM(R13:R15)/COUNT(R13:R15))
E14: C | I14: 2 | J14: Notulen/arahan pimpinan tentang integritas | L14: Ada | M14: Notulen Rapat Sosialisasi Budaya Disiplin Kerja | N14: Ya | O14: Ya | P14: Sesuai | R14: =IF(OR(L14="",L14="N/A"),"",IF(L14="Tidak Ada",0,IF(P14="","",IF(P14="Tidak Sesuai",0,IF(AND(N14="Ya",O14="Ya",P14="Sesuai"),1,0.5))))) | S14: =IF(L14="N/A","N/A",IF(R14="","Belum dinilai",IF(R14=1,"Memenuhi",IF(R14=0,"Tidak Memenuhi","Memenuhi Sebagian")))) | T14: 1.1-1
E15: C | I15: 3 | J15: Bukti pembinaan/penegakan disiplin, jika ada | R15: =IF(OR(L15="",L15="N/A"),"",IF(L15="Tidak Ada",0,IF(P15="","",IF(P15="Tidak Sesuai",0,IF(AND(N15="Ya",O15="Ya",P15="Sesuai"),1,0.5))))) | S15: =IF(L15="N/A","N/A",IF(R15="","Belum dinilai",IF(R15=1,"Memenuhi",IF(R15=0,"Tidak Memenuhi","Memenuhi Sebagian")))) | T15: 1.1-1
E16: D | F16: D – Komunikasi & Pemahaman | G16: Kebijakan penegakan integritas dan nilai etika organisasi telah dipahami oleh seluruh pegawai | H16: Kebijakan integritas dan nilai etika telah dikomunikasikan dan dipahami oleh pegawai | I16: 1 | J16: Daftar hadir sosialisasi | R16: =IF(OR(L16="",L16="N/A"),"",IF(L16="Tidak Ada",0,IF(P16="","",IF(P16="Tidak Sesuai",0,IF(AND(N16="Ya",O16="Ya",P16="Sesuai"),1,0.5))))) | S16: =IF(L16="N/A","N/A",IF(R16="","Belum dinilai",IF(R16=1,"Memenuhi",IF(R16=0,"Tidak Memenuhi","Memenuhi Sebagian")))) | T16: 1.1-1 | U16: =IF(COUNT(R16:R18)=0,"",SUM(R16:R18)/COUNT(R16:R18))
E17: D | I17: 2 | J17: Materi sosialisasi | L17: Ada | M17: Materi Presensi Aplikasi SIAP | N17: Ya | O17: Ya | P17: Sesuai | R17: =IF(OR(L17="",L17="N/A"),"",IF(L17="Tidak Ada",0,IF(P17="","",IF(P17="Tidak Sesuai",0,IF(AND(N17="Ya",O17="Ya",P17="Sesuai"),1,0.5))))) | S17: =IF(L17="N/A","N/A",IF(R17="","Belum dinilai",IF(R17=1,"Memenuhi",IF(R17=0,"Tidak Memenuhi","Memenuhi Sebagian")))) | T17: 1.1-1
E18: D | I18: 3 | J18: Notulen/berita acara sosialisasi | R18: =IF(OR(L18="",L18="N/A"),"",IF(L18="Tidak Ada",0,IF(P18="","",IF(P18="Tidak Sesuai",0,IF(AND(N18="Ya",O18="Ya",P18="Sesuai"),1,0.5))))) | S18: =IF(L18="N/A","N/A",IF(R18="","Belum dinilai",IF(R18=1,"Memenuhi",IF(R18=0,"Tidak Memenuhi","Memenuhi Sebagian")))) | T18: 1.1-1
E19: E | F19: E – Kebijakan/Formalitas | G19: Terdapat kebijakan penegakan integritas dan nilai etika untuk seluruh pegawai dalam organisasi | H19: Organisasi telah memiliki kebijakan/aturan mengenai integritas dan nilai etika | I19: 1 | J19: Kode Etik/Kode Perilaku | L19: Ada | M19: Perbub No 30 tahun 2018, SK Inspektur 211 Tahun 2018 | N19: Ya | O19: Ya | P19: Sesuai | R19: =IF(OR(L19="",L19="N/A"),"",IF(L19="Tidak Ada",0,IF(P19="","",IF(P19="Tidak Sesuai",0,IF(AND(N19="Ya",O19="Ya",P19="Sesuai"),1,0.5))))) | S19: =IF(L19="N/A","N/A",IF(R19="","Belum dinilai",IF(R19=1,"Memenuhi",IF(R19=0,"Tidak Memenuhi","Memenuhi Sebagian")))) | T19: 1.1-1 | U19: =IF(COUNT(R19:R21)=0,"",SUM(R19:R21)/COUNT(R19:R21))
E20: E | I20: 2 | J20: Pakta Integritas | R20: =IF(OR(L20="",L20="N/A"),"",IF(L20="Tidak Ada",0,IF(P20="","",IF(P20="Tidak Sesuai",0,IF(AND(N20="Ya",O20="Ya",P20="Sesuai"),1,0.5))))) | S20: =IF(L20="N/A","N/A",IF(R20="","Belum dinilai",IF(R20=1,"Memenuhi",IF(R20=0,"Tidak Memenuhi","Memenuhi Sebagian")))) | T20: 1.1-1
E21: E | I21: 3 | J21: Surat Edaran/Instruksi Kepala OPD tentang integritas | R21: =IF(OR(L21="",L21="N/A"),"",IF(L21="Tidak Ada",0,IF(P21="","",IF(P21="Tidak Sesuai",0,IF(AND(N21="Ya",O21="Ya",P21="Sesuai"),1,0.5))))) | S21: =IF(L21="N/A","N/A",IF(R21="","Belum dinilai",IF(R21=1,"Memenuhi",IF(R21=0,"Tidak Memenuhi","Memenuhi Sebagian")))) | T21: 1.1-1
A22: 1.2 | B22: Komitmen terhadap Kompetensi | C22: 1 | D22: Tugas dan jabatan dalam organisasi dilaksanakan dan diisi oleh SDM yang kompeten | E22: A | F22: A – Perbaikan Berkelanjutan | G22: Pengelolaan kompetensi SDM telah diperbaiki secara berkelanjutan dan secara optimal mampu mendukung pencapaian tujuan organisasi | H22: Pengelolaan kompetensi SDM telah diperbaiki secara berkelanjutan dan secara optimal mampu mendukung pencapaian tujuan organisasi | I22: 1 | J22: Laporan Evaluasi/Pemetaan Kompetensi Pegawai Tahun Berjalan | R22: =IF(OR(L22="",L22="N/A"),"",IF(L22="Tidak Ada",0,IF(P22="","",IF(P22="Tidak Sesuai",0,IF(AND(N22="Ya",O22="Ya",P22="Sesuai"),1,0.5))))) | S22: =IF(L22="N/A","N/A",IF(R22="","Belum dinilai",IF(R22=1,"Memenuhi",IF(R22=0,"Tidak Memenuhi","Memenuhi Sebagian")))) | T22: 1.2-1 | U22: =IF(COUNT(R22:R24)=0,"",SUM(R22:R24)/COUNT(R22:R24))
E23: A | I23: 2 | J23: Laporan Tindak Lanjut Pengembangan Kompetensi ASN | R23: =IF(OR(L23="",L23="N/A"),"",IF(L23="Tidak Ada",0,IF(P23="","",IF(P23="Tidak Sesuai",0,IF(AND(N23="Ya",O23="Ya",P23="Sesuai"),1,0.5))))) | S23: =IF(L23="N/A","N/A",IF(R23="","Belum dinilai",IF(R23=1,"Memenuhi",IF(R23=0,"Tidak Memenuhi","Memenuhi Sebagian")))) | T23: 1.2-1
E24: A | I24: 3 | J24: Dokumen Pemutakhiran Standar Kompetensi Jabatan | R24: =IF(OR(L24="",L24="N/A"),"",IF(L24="Tidak Ada",0,IF(P24="","",IF(P24="Tidak Sesuai",0,IF(AND(N24="Ya",O24="Ya",P24="Sesuai"),1,0.5))))) | S24: =IF(L24="N/A","N/A",IF(R24="","Belum dinilai",IF(R24=1,"Memenuhi",IF(R24=0,"Tidak Memenuhi","Memenuhi Sebagian")))) | T24: 1.2-1
E25: B | F25: B – Evaluasi & Tindak Lanjut | G25: Standar kompetensi organisasi dan implementasi/pemanfaatannya telah dievaluasi untuk mengetahui efektivitasnya | H25: Standar kompetensi organisasi dan implementasi/pemanfaatannya telah dievaluasi untuk mengetahui efektivitasnya | I25: 1 | J25: Laporan Evaluasi Penerapan Standar Kompetensi Jabatan | R25: =IF(OR(L25="",L25="N/A"),"",IF(L25="Tidak Ada",0,IF(P25="","",IF(P25="Tidak Sesuai",0,IF(AND(N25="Ya",O25="Ya",P25="Sesuai"),1,0.5))))) | S25: =IF(L25="N/A","N/A",IF(R25="","Belum dinilai",IF(R25=1,"Memenuhi",IF(R25=0,"Tidak Memenuhi","Memenuhi Sebagian")))) | T25: 1.2-1 | U25: =IF(COUNT(R25:R27)=0,"",SUM(R25:R27)/COUNT(R25:R27))
E26: B | I26: 2 | J26: Laporan Hasil Monitoring Kesesuaian Kompetensi Pegawai dengan Jabatan | R26: =IF(OR(L26="",L26="N/A"),"",IF(L26="Tidak Ada",0,IF(P26="","",IF(P26="Tidak Sesuai",0,IF(AND(N26="Ya",O26="Ya",P26="Sesuai"),1,0.5))))) | S26: =IF(L26="N/A","N/A",IF(R26="","Belum dinilai",IF(R26=1,"Memenuhi",IF(R26=0,"Tidak Memenuhi","Memenuhi Sebagian")))) | T26: 1.2-1
E27: B | I27: 3 | J27: Matriks Tindak Lanjut Hasil Evaluasi | R27: =IF(OR(L27="",L27="N/A"),"",IF(L27="Tidak Ada",0,IF(P27="","",IF(P27="Tidak Sesuai",0,IF(AND(N27="Ya",O27="Ya",P27="Sesuai"),1,0.5))))) | S27: =IF(L27="N/A","N/A",IF(R27="","Belum dinilai",IF(R27=1,"Memenuhi",IF(R27=0,"Tidak Memenuhi","Memenuhi Sebagian")))) | T27: 1.2-1
E28: C | F28: C – Implementasi | G28: Standar kompetensi telah diimplementasikan/dimanfaatkan dalam pengelolaan/pembinaan SDM organisasi | H28: Standar kompetensi telah diimplementasikan/dimanfaatkan dalam pengelolaan/pembinaan SDM organisasi | I28: 1 | J28: Matriks Pemetaan Kompetensi Pegawai | L28: Ada | M28: Matrik rencana usulan Diklat Substantif Tahun 2026 | N28: Ya | O28: Ya | P28: Sesuai | R28: =IF(OR(L28="",L28="N/A"),"",IF(L28="Tidak Ada",0,IF(P28="","",IF(P28="Tidak Sesuai",0,IF(AND(N28="Ya",O28="Ya",P28="Sesuai"),1,0.5))))) | S28: =IF(L28="N/A","N/A",IF(R28="","Belum dinilai",IF(R28=1,"Memenuhi",IF(R28=0,"Tidak Memenuhi","Memenuhi Sebagian")))) | T28: 1.2-1 | U28: =IF(COUNT(R28:R30)=0,"",SUM(R28:R30)/COUNT(R28:R30))
E29: C | I29: 2 | J29: Analisis Kesenjangan Kompetensi | R29: =IF(OR(L29="",L29="N/A"),"",IF(L29="Tidak Ada",0,IF(P29="","",IF(P29="Tidak Sesuai",0,IF(AND(N29="Ya",O29="Ya",P29="Sesuai"),1,0.5))))) | S29: =IF(L29="N/A","N/A",IF(R29="","Belum dinilai",IF(R29=1,"Memenuhi",IF(R29=0,"Tidak Memenuhi","Memenuhi Sebagian")))) | T29: 1.2-1
E30: C | I30: 3 | J30: Rencana Pengembangan Kompetensi ASN | R30: =IF(OR(L30="",L30="N/A"),"",IF(L30="Tidak Ada",0,IF(P30="","",IF(P30="Tidak Sesuai",0,IF(AND(N30="Ya",O30="Ya",P30="Sesuai"),1,0.5))))) | S30: =IF(L30="N/A","N/A",IF(R30="","Belum dinilai",IF(R30=1,"Memenuhi",IF(R30=0,"Tidak Memenuhi","Memenuhi Sebagian")))) | T30: 1.2-1
E31: D | F31: D – Komunikasi & Pemahaman | G31: Standar kompetensi telah dikomunikasikan dan dipahami oleh seluruh pegawai organisasi | H31: Standar kompetensi telah dikomunikasikan dan dipahami oleh seluruh pegawai organisasi | I31: 1 | J31: Standar Kompetensi Jabatan | R31: =IF(OR(L31="",L31="N/A"),"",IF(L31="Tidak Ada",0,IF(P31="","",IF(P31="Tidak Sesuai",0,IF(AND(N31="Ya",O31="Ya",P31="Sesuai"),1,0.5))))) | S31: =IF(L31="N/A","N/A",IF(R31="","Belum dinilai",IF(R31=1,"Memenuhi",IF(R31=0,"Tidak Memenuhi","Memenuhi Sebagian")))) | T31: 1.2-1 | U31: =IF(COUNT(R31:R33)=0,"",SUM(R31:R33)/COUNT(R31:R33))
E32: D | I32: 2 | J32: Bukti sosialisasi/penyampaian standar kompetensi | R32: =IF(OR(L32="",L32="N/A"),"",IF(L32="Tidak Ada",0,IF(P32="","",IF(P32="Tidak Sesuai",0,IF(AND(N32="Ya",O32="Ya",P32="Sesuai"),1,0.5))))) | S32: =IF(L32="N/A","N/A",IF(R32="","Belum dinilai",IF(R32=1,"Memenuhi",IF(R32=0,"Tidak Memenuhi","Memenuhi Sebagian")))) | T32: 1.2-1
E33: D | I33: 3 | J33: Daftar hadir/notulen. | R33: =IF(OR(L33="",L33="N/A"),"",IF(L33="Tidak Ada",0,IF(P33="","",IF(P33="Tidak Sesuai",0,IF(AND(N33="Ya",O33="Ya",P33="Sesuai"),1,0.5))))) | S33: =IF(L33="N/A","N/A",IF(R33="","Belum dinilai",IF(R33=1,"Memenuhi",IF(R33=0,"Tidak Memenuhi","Memenuhi Sebagian")))) | T33: 1.2-1
E34: E | F34: E – Kebijakan/Formalitas | G34: Terdapat standar kompetensi yang jelas untuk seluruh jabatan dan posisi dalam organisasi | H34: Terdapat standar kompetensi yang jelas untuk seluruh jabatan dan posisi dalam organisasi | I34: 1 | J34: Standar Kompetensi Jabatan | R34: =IF(OR(L34="",L34="N/A"),"",IF(L34="Tidak Ada",0,IF(P34="","",IF(P34="Tidak Sesuai",0,IF(AND(N34="Ya",O34="Ya",P34="Sesuai"),1,0.5))))) | S34: =IF(L34="N/A","N/A",IF(R34="","Belum dinilai",IF(R34=1,"Memenuhi",IF(R34=0,"Tidak Memenuhi","Memenuhi Sebagian")))) | T34: 1.2-1 | U34: =IF(COUNT(R34:R36)=0,"",SUM(R34:R36)/COUNT(R34:R36))
E35: E | I35: 2 | J35: Peta Jabatan | R35: =IF(OR(L35="",L35="N/A"),"",IF(L35="Tidak Ada",0,IF(P35="","",IF(P35="Tidak Sesuai",0,IF(AND(N35="Ya",O35="Ya",P35="Sesuai"),1,0.5))))) | S35: =IF(L35="N/A","N/A",IF(R35="","Belum dinilai",IF(R35=1,"Memenuhi",IF(R35=0,"Tidak Memenuhi","Memenuhi Sebagian")))) | T35: 1.2-1
E36: E | I36: 3 | J36: Anjab dan ABK. | R36: =IF(OR(L36="",L36="N/A"),"",IF(L36="Tidak Ada",0,IF(P36="","",IF(P36="Tidak Sesuai",0,IF(AND(N36="Ya",O36="Ya",P36="Sesuai"),1,0.5))))) | S36: =IF(L36="N/A","N/A",IF(R36="","Belum dinilai",IF(R36=1,"Memenuhi",IF(R36=0,"Tidak Memenuhi","Memenuhi Sebagian")))) | T36: 1.2-1
A37: 1.3 | B37: Kepemimpinan yang Kondusif | C37: 1 | D37: Pimpinan K/L/D menciptakan lingkungan kerja yang kondusif untuk mendukung ketaatan terhadap peraturan yang berlaku | E37: A | F37: A – Perbaikan Berkelanjutan | G37: Penerapan manajemen kinerja, pengelolaan keuangan, manajemen SDM, serta manajemen risiko dapat meningkatkan efektivitas dan efisiensi kinerja seluruh level pimpinan dan pegawai | H37: Penerapan manajemen kinerja, pengelolaan keuangan, manajemen SDM, serta manajemen risiko dapat meningkatkan efektivitas dan efisiensi kinerja seluruh level pimpinan dan pegawai | I37: 1 | J37: Laporan Kinerja/LKjIP OPD | R37: =IF(OR(L37="",L37="N/A"),"",IF(L37="Tidak Ada",0,IF(P37="","",IF(P37="Tidak Sesuai",0,IF(AND(N37="Ya",O37="Ya",P37="Sesuai"),1,0.5))))) | S37: =IF(L37="N/A","N/A",IF(R37="","Belum dinilai",IF(R37=1,"Memenuhi",IF(R37=0,"Tidak Memenuhi","Memenuhi Sebagian")))) | T37: 1.3-1 | U37: =IF(COUNT(R37:R39)=0,"",SUM(R37:R39)/COUNT(R37:R39))
E38: A | I38: 2 | J38: Laporan Evaluasi Penerapan Manajemen Kinerja, Keuangan, SDM, dan Manajemen Risiko | R38: =IF(OR(L38="",L38="N/A"),"",IF(L38="Tidak Ada",0,IF(P38="","",IF(P38="Tidak Sesuai",0,IF(AND(N38="Ya",O38="Ya",P38="Sesuai"),1,0.5))))) | S38: =IF(L38="N/A","N/A",IF(R38="","Belum dinilai",IF(R38=1,"Memenuhi",IF(R38=0,"Tidak Memenuhi","Memenuhi Sebagian")))) | T38: 1.3-1
E39: A | I39: 3 | J39: Dokumen/rekapitulasi capaian kinerja dan efisiensi | R39: =IF(OR(L39="",L39="N/A"),"",IF(L39="Tidak Ada",0,IF(P39="","",IF(P39="Tidak Sesuai",0,IF(AND(N39="Ya",O39="Ya",P39="Sesuai"),1,0.5))))) | S39: =IF(L39="N/A","N/A",IF(R39="","Belum dinilai",IF(R39=1,"Memenuhi",IF(R39=0,"Tidak Memenuhi","Memenuhi Sebagian")))) | T39: 1.3-1
E40: B | F40: B – Evaluasi & Tindak Lanjut | G40: Pimpinan organisasi melaksanakan evaluasi berkala atas kebijakan pengendalian intern dan berupaya mengatasi permasalahan yang berkaitan dengan lingkungan pengendalian yang kondusif | H40: Pimpinan organisasi melaksanakan evaluasi berkala atas kebijakan pengendalian intern dan berupaya mengatasi permasalahan yang berkaitan dengan lingkungan pengendalian yang kondusif | I40: 1 | J40: Laporan Evaluasi Lingkungan Pengendalian | R40: =IF(OR(L40="",L40="N/A"),"",IF(L40="Tidak Ada",0,IF(P40="","",IF(P40="Tidak Sesuai",0,IF(AND(N40="Ya",O40="Ya",P40="Sesuai"),1,0.5))))) | S40: =IF(L40="N/A","N/A",IF(R40="","Belum dinilai",IF(R40=1,"Memenuhi",IF(R40=0,"Tidak Memenuhi","Memenuhi Sebagian")))) | T40: 1.3-1 | U40: =IF(COUNT(R40:R42)=0,"",SUM(R40:R42)/COUNT(R40:R42))
E41: B | I41: 2 | J41: Matriks Tindak Lanjut Hasil Evaluasi | R41: =IF(OR(L41="",L41="N/A"),"",IF(L41="Tidak Ada",0,IF(P41="","",IF(P41="Tidak Sesuai",0,IF(AND(N41="Ya",O41="Ya",P41="Sesuai"),1,0.5))))) | S41: =IF(L41="N/A","N/A",IF(R41="","Belum dinilai",IF(R41=1,"Memenuhi",IF(R41=0,"Tidak Memenuhi","Memenuhi Sebagian")))) | T41: 1.3-1
...

Sheet Rekap Parameter
A1: REKAPITULASI HASIL PENJAMINAN KUALITAS / QUALITY ASSURANCE APIP PER PARAMETER DAN GRADE
A2: ="OPD: "&IF(Petunjuk!$C$5="","..........",Petunjuk!$C$5)&" | Tahun Penilaian: "&IF(Petunjuk!$C$6="","....",Petunjuk!$C$6)
A4: No | B4: Kode Subunsur | C4: Uraian Subunsur | D4: No Par. | E4: Uraian Parameter | F4: Jml Item | G4: Item N/A | H4: Item Dinilai | I4: Belum Dinilai | J4: % Grade E | K4: % Grade D | L4: % Grade C | M4: % Grade B | N4: % Grade A | O4: % Pemenuhan Parameter | P4: Grade Indikatif | Q4: Level Indikatif | R4: Grade berikutnya yang perlu dilengkapi
A5: 1 | B5: 1.1 | C5: Penegakan Integritas dan Nilai Etika | D5: 1 | E5: =IFERROR(INDEX(FILTER('KK Penjaminan Kualitas'!$D$6:$D$676,'KK Penjaminan Kualitas'!$A$6:$A$676=B5,'KK Penjaminan Kualitas'!$C$6:$C$676=D5),1),"") | F5: =COUNTIFS('KK Penjaminan Kualitas'!$T$6:$T$676,$S5,'KK Penjaminan Kualitas'!$J$6:$J$676,"<>") | G5: =COUNTIFS('KK Penjaminan Kualitas'!$T$6:$T$676,$S5,'KK Penjaminan Kualitas'!$L$6:$L$676,"N/A") | H5: =SUMPRODUCT(('KK Penjaminan Kualitas'!$T$6:$T$676=$S5)*ISNUMBER('KK Penjaminan Kualitas'!$R$6:$R$676)) | I5: =F5-G5-H5 | J5: =IFERROR(SUMIFS('KK Penjaminan Kualitas'!$R$6:$R$676,'KK Penjaminan Kualitas'!$T$6:$T$676,$S5,'KK Penjaminan Kualitas'!$E$6:$E$676,"E")/SUMPRODUCT(('KK Penjaminan Kualitas'!$T$6:$T$676=$S5)*('KK Penjaminan Kualitas'!$E$6:$E$676="E")*ISNUMBER('KK Penjaminan Kualitas'!$R$6:$R$676)),"") | K5: =IFERROR(SUMIFS('KK Penjaminan Kualitas'!$R$6:$R$676,'KK Penjaminan Kualitas'!$T$6:$T$676,$S5,'KK Penjaminan Kualitas'!$E$6:$E$676,"D")/SUMPRODUCT(('KK Penjaminan Kualitas'!$T$6:$T$676=$S5)*('KK Penjaminan Kualitas'!$E$6:$E$676="D")*ISNUMBER('KK Penjaminan Kualitas'!$R$6:$R$676)),"") | L5: =IFERROR(SUMIFS('KK Penjaminan Kualitas'!$R$6:$R$676,'KK Penjaminan Kualitas'!$T$6:$T$676,$S5,'KK Penjaminan Kualitas'!$E$6:$E$676,"C")/SUMPRODUCT(('KK Penjaminan Kualitas'!$T$6:$T$676=$S5)*('KK Penjaminan Kualitas'!$E$6:$E$676="C")*ISNUMBER('KK Penjaminan Kualitas'!$R$6:$R$676)),"") | M5: =IFERROR(SUMIFS('KK Penjaminan Kualitas'!$R$6:$R$676,'KK Penjaminan Kualitas'!$T$6:$T$676,$S5,'KK Penjaminan Kualitas'!$E$6:$E$676,"B")/SUMPRODUCT(('KK Penjaminan Kualitas'!$T$6:$T$676=$S5)*('KK Penjaminan Kualitas'!$E$6:$E$676="B")*ISNUMBER('KK Penjaminan Kualitas'!$R$6:$R$676)),"") | N5: =IFERROR(SUMIFS('KK Penjaminan Kualitas'!$R$6:$R$676,'KK Penjaminan Kualitas'!$T$6:$T$676,$S5,'KK Penjaminan Kualitas'!$E$6:$E$676,"A")/SUMPRODUCT(('KK Penjaminan Kualitas'!$T$6:$T$676=$S5)*('KK Penjaminan Kualitas'!$E$6:$E$676="A")*ISNUMBER('KK Penjaminan Kualitas'!$R$6:$R$676)),"") | O5: =IF(H5=0,"",SUMIFS('KK Penjaminan Kualitas'!$R$6:$R$676,'KK Penjaminan Kualitas'!$T$6:$T$676,$S5)/H5) | P5: =IF(Q5="","",IF(Q5=0,"< E",MID("EDCBA",Q5,1))) | Q5: =IF(H5=0,"",IF(NOT(AND(ISNUMBER(J5),J5>=Petunjuk!$C$14)),0,IF(NOT(AND(ISNUMBER(K5),K5>=Petunjuk!$C$14)),1,IF(NOT(AND(ISNUMBER(L5),L5>=Petunjuk!$C$14)),2,IF(NOT(AND(ISNUMBER(M5),M5>=Petunjuk!$C$14)),3,IF(NOT(AND(ISNUMBER(N5),N5>=Petunjuk!$C$14)),4,5)))))) | R5: =IF(Q5="","Belum dinilai",IF(Q5=5,"Seluruh grade terpenuhi","Lengkapi evidence Grade "&MID("EDCBA",Q5+1,1)&IF(I5>0," ("&I5&" item belum dinilai)",""))) | S5: 1.1-1
A6: 2 | B6: 1.2 | C6: Komitmen terhadap Kompetensi | D6: 1 | E6: =IFERROR(INDEX(FILTER('KK Penjaminan Kualitas'!$D$6:$D$676,'KK Penjaminan Kualitas'!$A$6:$A$676=B6,'KK Penjaminan Kualitas'!$C$6:$C$676=D6),1),"") | F6: =COUNTIFS('KK Penjaminan Kualitas'!$T$6:$T$676,$S6,'KK Penjaminan Kualitas'!$J$6:$J$676,"<>") | G6: =COUNTIFS('KK Penjaminan Kualitas'!$T$6:$T$676,$S6,'KK Penjaminan Kualitas'!$L$6:$L$676,"N/A") | H6: =SUMPRODUCT(('KK Penjaminan Kualitas'!$T$6:$T$676=$S6)*ISNUMBER('KK Penjaminan Kualitas'!$R$6:$R$676)) | I6: =F6-G6-H6 | J6: =IFERROR(SUMIFS('KK Penjaminan Kualitas'!$R$6:$R$676,'KK Penjaminan Kualitas'!$T$6:$T$676,$S6,'KK Penjaminan Kualitas'!$E$6:$E$676,"E")/SUMPRODUCT(('KK Penjaminan Kualitas'!$T$6:$T$676=$S6)*('KK Penjaminan Kualitas'!$E$6:$E$676="E")*ISNUMBER('KK Penjaminan Kualitas'!$R$6:$R$676)),"") | K6: =IFERROR(SUMIFS('KK Penjaminan Kualitas'!$R$6:$R$676,'KK Penjaminan Kualitas'!$T$6:$T$676,$S6,'KK Penjaminan Kualitas'!$E$6:$E$676,"D")/SUMPRODUCT(('KK Penjaminan Kualitas'!$T$6:$T$676=$S6)*('KK Penjaminan Kualitas'!$E$6:$E$676="D")*ISNUMBER('KK Penjaminan Kualitas'!$R$6:$R$676)),"") | L6: =IFERROR(SUMIFS('KK Penjaminan Kualitas'!$R$6:$R$676,'KK Penjaminan Kualitas'!$T$6:$T$676,$S6,'KK Penjaminan Kualitas'!$E$6:$E$676,"C")/SUMPRODUCT(('KK Penjaminan Kualitas'!$T$6:$T$676=$S6)*('KK Penjaminan Kualitas'!$E$6:$E$676="C")*ISNUMBER('KK Penjaminan Kualitas'!$R$6:$R$676)),"") | M6: =IFERROR(SUMIFS('KK Penjaminan Kualitas'!$R$6:$R$676,'KK Penjaminan Kualitas'!$T$6:$T$676,$S6,'KK Penjaminan Kualitas'!$E$6:$E$676,"B")/SUMPRODUCT(('KK Penjaminan Kualitas'!$T$6:$T$676=$S6)*('KK Penjaminan Kualitas'!$E$6:$E$676="B")*ISNUMBER('KK Penjaminan Kualitas'!$R$6:$R$676)),"") | N6: =IFERROR(SUMIFS('KK Penjaminan Kualitas'!$R$6:$R$676,'KK Penjaminan Kualitas'!$T$6:$T$676,$S6,'KK Penjaminan Kualitas'!$E$6:$E$676,"A")/SUMPRODUCT(('KK Penjaminan Kualitas'!$T$6:$T$676=$S6)*('KK Penjaminan Kualitas'!$E$6:$E$676="A")*ISNUMBER('KK Penjaminan Kualitas'!$R$6:$R$676)),"") | O6: =IF(H6=0,"",SUMIFS('KK Penjaminan Kualitas'!$R$6:$R$676,'KK Penjaminan Kualitas'!$T$6:$T$676,$S6)/H6) | P6: =IF(Q6="","",IF(Q6=0,"< E",MID("EDCBA",Q6,1))) | Q6: =IF(H6=0,"",IF(NOT(AND(ISNUMBER(J6),J6>=Petunjuk!$C$14)),0,IF(NOT(AND(ISNUMBER(K6),K6>=Petunjuk!$C$14)),1,IF(NOT(AND(ISNUMBER(L6),L6>=Petunjuk!$C$14)),2,IF(NOT(AND(ISNUMBER(M6),M6>=Petunjuk!$C$14)),3,IF(NOT(AND(ISNUMBER(N6),N6>=Petunjuk!$C$14)),4,5)))))) | R6: =IF(Q6="","Belum dinilai",IF(Q6=5,"Seluruh grade terpenuhi","Lengkapi evidence Grade "&MID("EDCBA",Q6+1,1)&IF(I6>0," ("&I6&" item belum dinilai)",""))) | S6: 1.2-1
A7: 3 | B7: 1.3 | C7: Kepemimpinan yang Kondusif | D7: 1 | E7: =IFERROR(INDEX(FILTER('KK Penjaminan Kualitas'!$D$6:$D$676,'KK Penjaminan Kualitas'!$A$6:$A$676=B7,'KK Penjaminan Kualitas'!$C$6:$C$676=D7),1),"") | F7: =COUNTIFS('KK Penjaminan Kualitas'!$T$6:$T$676,$S7,'KK Penjaminan Kualitas'!$J$6:$J$676,"<>") | G7: =COUNTIFS('KK Penjaminan Kualitas'!$T$6:$T$676,$S7,'KK Penjaminan Kualitas'!$L$6:$L$676,"N/A") | H7: =SUMPRODUCT(('KK Penjaminan Kualitas'!$T$6:$T$676=$S7)*ISNUMBER('KK Penjaminan Kualitas'!$R$6:$R$676)) | I7: =F7-G7-H7 | J7: =IFERROR(SUMIFS('KK Penjaminan Kualitas'!$R$6:$R$676,'KK Penjaminan Kualitas'!$T$6:$T$676,$S7,'KK Penjaminan Kualitas'!$E$6:$E$676,"E")/SUMPRODUCT(('KK Penjaminan Kualitas'!$T$6:$T$676=$S7)*('KK Penjaminan Kualitas'!$E$6:$E$676="E")*ISNUMBER('KK Penjaminan Kualitas'!$R$6:$R$676)),"") | K7: =IFERROR(SUMIFS('KK Penjaminan Kualitas'!$R$6:$R$676,'KK Penjaminan Kualitas'!$T$6:$T$676,$S7,'KK Penjaminan Kualitas'!$E$6:$E$676,"D")/SUMPRODUCT(('KK Penjaminan Kualitas'!$T$6:$T$676=$S7)*('KK Penjaminan Kualitas'!$E$6:$E$676="D")*ISNUMBER('KK Penjaminan Kualitas'!$R$6:$R$676)),"") | L7: =IFERROR(SUMIFS('KK Penjaminan Kualitas'!$R$6:$R$676,'KK Penjaminan Kualitas'!$T$6:$T$676,$S7,'KK Penjaminan Kualitas'!$E$6:$E$676,"C")/SUMPRODUCT(('KK Penjaminan Kualitas'!$T$6:$T$676=$S7)*('KK Penjaminan Kualitas'!$E$6:$E$676="C")*ISNUMBER('KK Penjaminan Kualitas'!$R$6:$R$676)),"") | M7: =IFERROR(SUMIFS('KK Penjaminan Kualitas'!$R$6:$R$676,'KK Penjaminan Kualitas'!$T$6:$T$676,$S7,'KK Penjaminan Kualitas'!$E$6:$E$676,"B")/SUMPRODUCT(('KK Penjaminan Kualitas'!$T$6:$T$676=$S7)*('KK Penjaminan Kualitas'!$E$6:$E$676="B")*ISNUMBER('KK Penjaminan Kualitas'!$R$6:$R$676)),"") | N7: =IFERROR(SUMIFS('KK Penjaminan Kualitas'!$R$6:$R$676,'KK Penjaminan Kualitas'!$T$6:$T$676,$S7,'KK Penjaminan Kualitas'!$E$6:$E$676,"A")/SUMPRODUCT(('KK Penjaminan Kualitas'!$T$6:$T$676=$S7)*('KK Penjaminan Kualitas'!$E$6:$E$676="A")*ISNUMBER('KK Penjaminan Kualitas'!$R$6:$R$676)),"") | O7: =IF(H7=0,"",SUMIFS('KK Penjaminan Kualitas'!$R$6:$R$676,'KK Penjaminan Kualitas'!$T$6:$T$676,$S7)/H7) | P7: =IF(Q7="","",IF(Q7=0,"< E",MID("EDCBA",Q7,1))) | Q7: =IF(H7=0,"",IF(NOT(AND(ISNUMBER(J7),J7>=Petunjuk!$C$14)),0,IF(NOT(AND(ISNUMBER(K7),K7>=Petunjuk!$C$14)),1,IF(NOT(AND(ISNUMBER(L7),L7>=Petunjuk!$C$14)),2,IF(NOT(AND(ISNUMBER(M7),M7>=Petunjuk!$C$14)),3,IF(NOT(AND(ISNUMBER(N7),N7>=Petunjuk!$C$14)),4,5)))))) | R7: =IF(Q7="","Belum dinilai",IF(Q7=5,"Seluruh grade terpenuhi","Lengkapi evidence Grade "&MID("EDCBA",Q7+1,1)&IF(I7>0," ("&I7&" item belum dinilai)",""))) | S7: 1.3-1
A8: 4 | B8: 1.3 | C8: Kepemimpinan yang Kondusif | D8: 2 | E8: =IFERROR(INDEX(FILTER('KK Penjaminan Kualitas'!$D$6:$D$676,'KK Penjaminan Kualitas'!$A$6:$A$676=B8,'KK Penjaminan Kualitas'!$C$6:$C$676=D8),1),"") | F8: =COUNTIFS('KK Penjaminan Kualitas'!$T$6:$T$676,$S8,'KK Penjaminan Kualitas'!$J$6:$J$676,"<>") | G8: =COUNTIFS('KK Penjaminan Kualitas'!$T$6:$T$676,$S8,'KK Penjaminan Kualitas'!$L$6:$L$676,"N/A") | H8: =SUMPRODUCT(('KK Penjaminan Kualitas'!$T$6:$T$676=$S8)*ISNUMBER('KK Penjaminan Kualitas'!$R$6:$R$676)) | I8: =F8-G8-H8 | J8: =IFERROR(SUMIFS('KK Penjaminan Kualitas'!$R$6:$R$676,'KK Penjaminan Kualitas'!$T$6:$T$676,$S8,'KK Penjaminan Kualitas'!$E$6:$E$676,"E")/SUMPRODUCT(('KK Penjaminan Kualitas'!$T$6:$T$676=$S8)*('KK Penjaminan Kualitas'!$E$6:$E$676="E")*ISNUMBER('KK Penjaminan Kualitas'!$R$6:$R$676)),"") | K8: =IFERROR(SUMIFS('KK Penjaminan Kualitas'!$R$6:$R$676,'KK Penjaminan Kualitas'!$T$6:$T$676,$S8,'KK Penjaminan Kualitas'!$E$6:$E$676,"D")/SUMPRODUCT(('KK Penjaminan Kualitas'!$T$6:$T$676=$S8)*('KK Penjaminan Kualitas'!$E$6:$E$676="D")*ISNUMBER('KK Penjaminan Kualitas'!$R$6:$R$676)),"") | L8: =IFERROR(SUMIFS('KK Penjaminan Kualitas'!$R$6:$R$676,'KK Penjaminan Kualitas'!$T$6:$T$676,$S8,'KK Penjaminan Kualitas'!$E$6:$E$676,"C")/SUMPRODUCT(('KK Penjaminan Kualitas'!$T$6:$T$676=$S8)*('KK Penjaminan Kualitas'!$E$6:$E$676="C")*ISNUMBER('KK Penjaminan Kualitas'!$R$6:$R$676)),"") | M8: =IFERROR(SUMIFS('KK Penjaminan Kualitas'!$R$6:$R$676,'KK Penjaminan Kualitas'!$T$6:$T$676,$S8,'KK Penjaminan Kualitas'!$E$6:$E$676,"B")/SUMPRODUCT(('KK Penjaminan Kualitas'!$T$6:$T$676=$S8)*('KK Penjaminan Kualitas'!$E$6:$E$676="B")*ISNUMBER('KK Penjaminan Kualitas'!$R$6:$R$676)),"") | N8: =IFERROR(SUMIFS('KK Penjaminan Kualitas'!$R$6:$R$676,'KK Penjaminan Kualitas'!$T$6:$T$676,$S8,'KK Penjaminan Kualitas'!$E$6:$E$676,"A")/SUMPRODUCT(('KK Penjaminan Kualitas'!$T$6:$T$676=$S8)*('KK Penjaminan Kualitas'!$E$6:$E$676="A")*ISNUMBER('KK Penjaminan Kualitas'!$R$6:$R$676)),"") | O8: =IF(H8=0,"",SUMIFS('KK Penjaminan Kualitas'!$R$6:$R$676,'KK Penjaminan Kualitas'!$T$6:$T$676,$S8)/H8) | P8: =IF(Q8="","",IF(Q8=0,"< E",MID("EDCBA",Q8,1))) | Q8: =IF(H8=0,"",IF(NOT(AND(ISNUMBER(J8),J8>=Petunjuk!$C$14)),0,IF(NOT(AND(ISNUMBER(K8),K8>=Petunjuk!$C$14)),1,IF(NOT(AND(ISNUMBER(L8),L8>=Petunjuk!$C$14)),2,IF(NOT(AND(ISNUMBER(M8),M8>=Petunjuk!$C$14)),3,IF(NOT(AND(ISNUMBER(N8),N8>=Petunjuk!$C$14)),4,5)))))) | R8: =IF(Q8="","Belum dinilai",IF(Q8=5,"Seluruh grade terpenuhi","Lengkapi evidence Grade "&MID("EDCBA",Q8+1,1)&IF(I8>0," ("&I8&" item belum dinilai)",""))) | S8: 1.3-2
A9: 5 | B9: 1.3 | C9: Kepemimpinan yang Kondusif | D9: 3 | E9: =IFERROR(INDEX(FILTER('KK Penjaminan Kualitas'!$D$6:$D$676,'KK Penjaminan Kualitas'!$A$6:$A$676=B9,'KK Penjaminan Kualitas'!$C$6:$C$676=D9),1),"") | F9: =COUNTIFS('KK Penjaminan Kualitas'!$T$6:$T$676,$S9,'KK Penjaminan Kualitas'!$J$6:$J$676,"<>") | G9: =COUNTIFS('KK Penjaminan Kualitas'!$T$6:$T$676,$S9,'KK Penjaminan Kualitas'!$L$6:$L$676,"N/A") | H9: =SUMPRODUCT(('KK Penjaminan Kualitas'!$T$6:$T$676=$S9)*ISNUMBER('KK Penjaminan Kualitas'!$R$6:$R$676)) | I9: =F9-G9-H9 | J9: =IFERROR(SUMIFS('KK Penjaminan Kualitas'!$R$6:$R$676,'KK Penjaminan Kualitas'!$T$6:$T$676,$S9,'KK Penjaminan Kualitas'!$E$6:$E$676,"E")/SUMPRODUCT(('KK Penjaminan Kualitas'!$T$6:$T$676=$S9)*('KK Penjaminan Kualitas'!$E$6:$E$676="E")*ISNUMBER('KK Penjaminan Kualitas'!$R$6:$R$676)),"") | K9: =IFERROR(SUMIFS('KK Penjaminan Kualitas'!$R$6:$R$676,'KK Penjaminan Kualitas'!$T$6:$T$676,$S9,'KK Penjaminan Kualitas'!$E$6:$E$676,"D")/SUMPRODUCT(('KK Penjaminan Kualitas'!$T$6:$T$676=$S9)*('KK Penjaminan Kualitas'!$E$6:$E$676="D")*ISNUMBER('KK Penjaminan Kualitas'!$R$6:$R$676)),"") | L9: =IFERROR(SUMIFS('KK Penjaminan Kualitas'!$R$6:$R$676,'KK Penjaminan Kualitas'!$T$6:$T$676,$S9,'KK Penjaminan Kualitas'!$E$6:$E$676,"C")/SUMPRODUCT(('KK Penjaminan Kualitas'!$T$6:$T$676=$S9)*('KK Penjaminan Kualitas'!$E$6:$E$676="C")*ISNUMBER('KK Penjaminan Kualitas'!$R$6:$R$676)),"") | M9: =IFERROR(SUMIFS('KK Penjaminan Kualitas'!$R$6:$R$676,'KK Penjaminan Kualitas'!$T$6:$T$676,$S9,'KK Penjaminan Kualitas'!$E$6:$E$676,"B")/SUMPRODUCT(('KK Penjaminan Kualitas'!$T$6:$T$676=$S9)*('KK Penjaminan Kualitas'!$E$6:$E$676="B")*ISNUMBER('KK Penjaminan Kualitas'!$R$6:$R$676)),"") | N9: =IFERROR(SUMIFS('KK Penjaminan Kualitas'!$R$6:$R$676,'KK Penjaminan Kualitas'!$T$6:$T$676,$S9,'KK Penjaminan Kualitas'!$E$6:$E$676,"A")/SUMPRODUCT(('KK Penjaminan Kualitas'!$T$6:$T$676=$S9)*('KK Penjaminan Kualitas'!$E$6:$E$676="A")*ISNUMBER('KK Penjaminan Kualitas'!$R$6:$R$676)),"") | O9: =IF(H9=0,"",SUMIFS('KK Penjaminan Kualitas'!$R$6:$R$676,'KK Penjaminan Kualitas'!$T$6:$T$676,$S9)/H9) | P9: =IF(Q9="","",IF(Q9=0,"< E",MID("EDCBA",Q9,1))) | Q9: =IF(H9=0,"",IF(NOT(AND(ISNUMBER(J9),J9>=Petunjuk!$C$14)),0,IF(NOT(AND(ISNUMBER(K9),K9>=Petunjuk!$C$14)),1,IF(NOT(AND(ISNUMBER(L9),L9>=Petunjuk!$C$14)),2,IF(NOT(AND(ISNUMBER(M9),M9>=Petunjuk!$C$14)),3,IF(NOT(AND(ISNUMBER(N9),N9>=Petunjuk!$C$14)),4,5)))))) | R9: =IF(Q9="","Belum dinilai",IF(Q9=5,"Seluruh grade terpenuhi","Lengkapi evidence Grade "&MID("EDCBA",Q9+1,1)&IF(I9>0," ("&I9&" item belum dinilai)",""))) | S9: 1.3-3
A10: 6 | B10: 1.3 | C10: Kepemimpinan yang Kondusif | D10: 4 | E10: =IFERROR(INDEX(FILTER('KK Penjaminan Kualitas'!$D$6:$D$676,'KK Penjaminan Kualitas'!$A$6:$A$676=B10,'KK Penjaminan Kualitas'!$C$6:$C$676=D10),1),"") | F10: =COUNTIFS('KK Penjaminan Kualitas'!$T$6:$T$676,$S10,'KK Penjaminan Kualitas'!$J$6:$J$676,"<>") | G10: =COUNTIFS('KK Penjaminan Kualitas'!$T$6:$T$676,$S10,'KK Penjaminan Kualitas'!$L$6:$L$676,"N/A") | H10: =SUMPRODUCT(('KK Penjaminan Kualitas'!$T$6:$T$676=$S10)*ISNUMBER('KK Penjaminan Kualitas'!$R$6:$R$676)) | I10: =F10-G10-H10 | J10: =IFERROR(SUMIFS('KK Penjaminan Kualitas'!$R$6:$R$676,'KK Penjaminan Kualitas'!$T$6:$T$676,$S10,'KK Penjaminan Kualitas'!$E$6:$E$676,"E")/SUMPRODUCT(('KK Penjaminan Kualitas'!$T$6:$T$676=$S10)*('KK Penjaminan Kualitas'!$E$6:$E$676="E")*ISNUMBER('KK Penjaminan Kualitas'!$R$6:$R$676)),"") | K10: =IFERROR(SUMIFS('KK Penjaminan Kualitas'!$R$6:$R$676,'KK Penjaminan Kualitas'!$T$6:$T$676,$S10,'KK Penjaminan Kualitas'!$E$6:$E$676,"D")/SUMPRODUCT(('KK Penjaminan Kualitas'!$T$6:$T$676=$S10)*('KK Penjaminan Kualitas'!$E$6:$E$676="D")*ISNUMBER('KK Penjaminan Kualitas'!$R$6:$R$676)),"") | L10: =IFERROR(SUMIFS('KK Penjaminan Kualitas'!$R$6:$R$676,'KK Penjaminan Kualitas'!$T$6:$T$676,$S10,'KK Penjaminan Kualitas'!$E$6:$E$676,"C")/SUMPRODUCT(('KK Penjaminan Kualitas'!$T$6:$T$676=$S10)*('KK Penjaminan Kualitas'!$E$6:$E$676="C")*ISNUMBER('KK Penjaminan Kualitas'!$R$6:$R$676)),"") | M10: =IFERROR(SUMIFS('KK Penjaminan Kualitas'!$R$6:$R$676,'KK Penjaminan Kualitas'!$T$6:$T$676,$S10,'KK Penjaminan Kualitas'!$E$6:$E$676,"B")/SUMPRODUCT(('KK Penjaminan Kualitas'!$T$6:$T$676=$S10)*('KK Penjaminan Kualitas'!$E$6:$E$676="B")*ISNUMBER('KK Penjaminan Kualitas'!$R$6:$R$676)),"") | N10: =IFERROR(SUMIFS('KK Penjaminan Kualitas'!$R$6:$R$676,'KK Penjaminan Kualitas'!$T$6:$T$676,$S10,'KK Penjaminan Kualitas'!$E$6:$E$676,"A")/SUMPRODUCT(('KK Penjaminan Kualitas'!$T$6:$T$676=$S10)*('KK Penjaminan Kualitas'!$E$6:$E$676="A")*ISNUMBER('KK Penjaminan Kualitas'!$R$6:$R$676)),"") | O10: =IF(H10=0,"",SUMIFS('KK Penjaminan Kualitas'!$R$6:$R$676,'KK Penjaminan Kualitas'!$T$6:$T$676,$S10)/H10) | P10: =IF(Q10="","",IF(Q10=0,"< E",MID("EDCBA",Q10,1))) | Q10: =IF(H10=0,"",IF(NOT(AND(ISNUMBER(J10),J10>=Petunjuk!$C$14)),0,IF(NOT(AND(ISNUMBER(K10),K10>=Petunjuk!$C$14)),1,IF(NOT(AND(ISNUMBER(L10),L10>=Petunjuk!$C$14)),2,IF(NOT(AND(ISNUMBER(M10),M10>=Petunjuk!$C$14)),3,IF(NOT(AND(ISNUMBER(N10),N10>=Petunjuk!$C$14)),4,5)))))) | R10: =IF(Q10="","Belum dinilai",IF(Q10=5,"Seluruh grade terpenuhi","Lengkapi evidence Grade "&MID("EDCBA",Q10+1,1)&IF(I10>0," ("&I10&" item belum dinilai)",""))) | S10: 1.3-4
A11: 7 | B11: 1.4 | C11: Struktur Organisasi Sesuai Kebutuhan | D11: 1 | E11: =IFERROR(INDEX(FILTER('KK Penjaminan Kualitas'!$D$6:$D$676,'KK Penjaminan Kualitas'!$A$6:$A$676=B11,'KK Penjaminan Kualitas'!$C$6:$C$676=D11),1),"") | F11: =COUNTIFS('KK Penjaminan Kualitas'!$T$6:$T$676,$S11,'KK Penjaminan Kualitas'!$J$6:$J$676,"<>") | G11: =COUNTIFS('KK Penjaminan Kualitas'!$T$6:$T$676,$S11,'KK Penjaminan Kualitas'!$L$6:$L$676,"N/A") | H11: =SUMPRODUCT(('KK Penjaminan Kualitas'!$T$6:$T$676=$S11)*ISNUMBER('KK Penjaminan Kualitas'!$R$6:$R$676)) | I11: =F11-G11-H11 | J11: =IFERROR(SUMIFS('KK Penjaminan Kualitas'!$R$6:$R$676,'KK Penjaminan Kualitas'!$T$6:$T$676,$S11,'KK Penjaminan Kualitas'!$E$6:$E$676,"E")/SUMPRODUCT(('KK Penjaminan Kualitas'!$T$6:$T$676=$S11)*('KK Penjaminan Kualitas'!$E$6:$E$676="E")*ISNUMBER('KK Penjaminan Kualitas'!$R$6:$R$676)),"") | K11: =IFERROR(SUMIFS('KK Penjaminan Kualitas'!$R$6:$R$676,'KK Penjaminan Kualitas'!$T$6:$T$676,$S11,'KK Penjaminan Kualitas'!$E$6:$E$676,"D")/SUMPRODUCT(('KK Penjaminan Kualitas'!$T$6:$T$676=$S11)*('KK Penjaminan Kualitas'!$E$6:$E$676="D")*ISNUMBER('KK Penjaminan Kualitas'!$R$6:$R$676)),"") | L11: =IFERROR(SUMIFS('KK Penjaminan Kualitas'!$R$6:$R$676,'KK Penjaminan Kualitas'!$T$6:$T$676,$S11,'KK Penjaminan Kualitas'!$E$6:$E$676,"C")/SUMPRODUCT(('KK Penjaminan Kualitas'!$T$6:$T$676=$S11)*('KK Penjaminan Kualitas'!$E$6:$E$676="C")*ISNUMBER('KK Penjaminan Kualitas'!$R$6:$R$676)),"") | M11: =IFERROR(SUMIFS('KK Penjaminan Kualitas'!$R$6:$R$676,'KK Penjaminan Kualitas'!$T$6:$T$676,$S11,'KK Penjaminan Kualitas'!$E$6:$E$676,"B")/SUMPRODUCT(('KK Penjaminan Kualitas'!$T$6:$T$676=$S11)*('KK Penjaminan Kualitas'!$E$6:$E$676="B")*ISNUMBER('KK Penjaminan Kualitas'!$R$6:$R$676)),"") | N11: =IFERROR(SUMIFS('KK Penjaminan Kualitas'!$R$6:$R$676,'KK Penjaminan Kualitas'!$T$6:$T$676,$S11,'KK Penjaminan Kualitas'!$E$6:$E$676,"A")/SUMPRODUCT(('KK Penjaminan Kualitas'!$T$6:$T$676=$S11)*('KK Penjaminan Kualitas'!$E$6:$E$676="A")*ISNUMBER('KK Penjaminan Kualitas'!$R$6:$R$676)),"") | O11: =IF(H11=0,"",SUMIFS('KK Penjaminan Kualitas'!$R$6:$R$676,'KK Penjaminan Kualitas'!$T$6:$T$676,$S11)/H11) | P11: =IF(Q11="","",IF(Q11=0,"< E",MID("EDCBA",Q11,1))) | Q11: =IF(H11=0,"",IF(NOT(AND(ISNUMBER(J11),J11>=Petunjuk!$C$14)),0,IF(NOT(AND(ISNUMBER(K11),K11>=Petunjuk!$C$14)),1,IF(NOT(AND(ISNUMBER(L11),L11>=Petunjuk!$C$14)),2,IF(NOT(AND(ISNUMBER(M11),M11>=Petunjuk!$C$14)),3,IF(NOT(AND(ISNUMBER(N11),N11>=Petunjuk!$C$14)),4,5)))))) | R11: =IF(Q11="","Belum dinilai",IF(Q11=5,"Seluruh grade terpenuhi","Lengkapi evidence Grade "&MID("EDCBA",Q11+1,1)&IF(I11>0," ("&I11&" item belum dinilai)",""))) | S11: 1.4-1
A12: 8 | B12: 1.5 | C12: Pendelegasian Wewenang dan Tanggung Jawab yang Tepat | D12: 1 | E12: =IFERROR(INDEX(FILTER('KK Penjaminan Kualitas'!$D$6:$D$676,'KK Penjaminan Kualitas'!$A$6:$A$676=B12,'KK Penjaminan Kualitas'!$C$6:$C$676=D12),1),"") | F12: =COUNTIFS('KK Penjaminan Kualitas'!$T$6:$T$676,$S12,'KK Penjaminan Kualitas'!$J$6:$J$676,"<>") | G12: =COUNTIFS('KK Penjaminan Kualitas'!$T$6:$T$676,$S12,'KK Penjaminan Kualitas'!$L$6:$L$676,"N/A") | H12: =SUMPRODUCT(('KK Penjaminan Kualitas'!$T$6:$T$676=$S12)*ISNUMBER('KK Penjaminan Kualitas'!$R$6:$R$676)) | I12: =F12-G12-H12 | J12: =IFERROR(SUMIFS('KK Penjaminan Kualitas'!$R$6:$R$676,'KK Penjaminan Kualitas'!$T$6:$T$676,$S12,'KK Penjaminan Kualitas'!$E$6:$E$676,"E")/SUMPRODUCT(('KK Penjaminan Kualitas'!$T$6:$T$676=$S12)*('KK Penjaminan Kualitas'!$E$6:$E$676="E")*ISNUMBER('KK Penjaminan Kualitas'!$R$6:$R$676)),"") | K12: =IFERROR(SUMIFS('KK Penjaminan Kualitas'!$R$6:$R$676,'KK Penjaminan Kualitas'!$T$6:$T$676,$S12,'KK Penjaminan Kualitas'!$E$6:$E$676,"D")/SUMPRODUCT(('KK Penjaminan Kualitas'!$T$6:$T$676=$S12)*('KK Penjaminan Kualitas'!$E$6:$E$676="D")*ISNUMBER('KK Penjaminan Kualitas'!$R$6:$R$676)),"") | L12: =IFERROR(SUMIFS('KK Penjaminan Kualitas'!$R$6:$R$676,'KK Penjaminan Kualitas'!$T$6:$T$676,$S12,'KK Penjaminan Kualitas'!$E$6:$E$676,"C")/SUMPRODUCT(('KK Penjaminan Kualitas'!$T$6:$T$676=$S12)*('KK Penjaminan Kualitas'!$E$6:$E$676="C")*ISNUMBER('KK Penjaminan Kualitas'!$R$6:$R$676)),"") | M12: =IFERROR(SUMIFS('KK Penjaminan Kualitas'!$R$6:$R$676,'KK Penjaminan Kualitas'!$T$6:$T$676,$S12,'KK Penjaminan Kualitas'!$E$6:$E$676,"B")/SUMPRODUCT(('KK Penjaminan Kualitas'!$T$6:$T$676=$S12)*('KK Penjaminan Kualitas'!$E$6:$E$676="B")*ISNUMBER('KK Penjaminan Kualitas'!$R$6:$R$676)),"") | N12: =IFERROR(SUMIFS('KK Penjaminan Kualitas'!$R$6:$R$676,'KK Penjaminan Kualitas'!$T$6:$T$676,$S12,'KK Penjaminan Kualitas'!$E$6:$E$676,"A")/SUMPRODUCT(('KK Penjaminan Kualitas'!$T$6:$T$676=$S12)*('KK Penjaminan Kualitas'!$E$6:$E$676="A")*ISNUMBER('KK Penjaminan Kualitas'!$R$6:$R$676)),"") | O12: =IF(H12=0,"",SUMIFS('KK Penjaminan Kualitas'!$R$6:$R$676,'KK Penjaminan Kualitas'!$T$6:$T$676,$S12)/H12) | P12: =IF(Q12="","",IF(Q12=0,"< E",MID("EDCBA",Q12,1))) | Q12: =IF(H12=0,"",IF(NOT(AND(ISNUMBER(J12),J12>=Petunjuk!$C$14)),0,IF(NOT(AND(ISNUMBER(K12),K12>=Petunjuk!$C$14)),1,IF(NOT(AND(ISNUMBER(L12),L12>=Petunjuk!$C$14)),2,IF(NOT(AND(ISNUMBER(M12),M12>=Petunjuk!$C$14)),3,IF(NOT(AND(ISNUMBER(N12),N12>=Petunjuk!$C$14)),4,5)))))) | R12: =IF(Q12="","Belum dinilai",IF(Q12=5,"Seluruh grade terpenuhi","Lengkapi evidence Grade "&MID("EDCBA",Q12+1,1)&IF(I12>0," ("&I12&" item belum dinilai)",""))) | S12: 1.5-1
A13: 9 | B13: 1.6 | C13: Penyusunan dan Penerapan Kebijakan yang Sehat tentang Pembinaan SDM | D13: 1 | E13: =IFERROR(INDEX(FILTER('KK Penjaminan Kualitas'!$D$6:$D$676,'KK Penjaminan Kualitas'!$A$6:$A$676=B13,'KK Penjaminan Kualitas'!$C$6:$C$676=D13),1),"") | F13: =COUNTIFS('KK Penjaminan Kualitas'!$T$6:$T$676,$S13,'KK Penjaminan Kualitas'!$J$6:$J$676,"<>") | G13: =COUNTIFS('KK Penjaminan Kualitas'!$T$6:$T$676,$S13,'KK Penjaminan Kualitas'!$L$6:$L$676,"N/A") | H13: =SUMPRODUCT(('KK Penjaminan Kualitas'!$T$6:$T$676=$S13)*ISNUMBER('KK Penjaminan Kualitas'!$R$6:$R$676)) | I13: =F13-G13-H13 | J13: =IFERROR(SUMIFS('KK Penjaminan Kualitas'!$R$6:$R$676,'KK Penjaminan Kualitas'!$T$6:$T$676,$S13,'KK Penjaminan Kualitas'!$E$6:$E$676,"E")/SUMPRODUCT(('KK Penjaminan Kualitas'!$T$6:$T$676=$S13)*('KK Penjaminan Kualitas'!$E$6:$E$676="E")*ISNUMBER('KK Penjaminan Kualitas'!$R$6:$R$676)),"") | K13: =IFERROR(SUMIFS('KK Penjaminan Kualitas'!$R$6:$R$676,'KK Penjaminan Kualitas'!$T$6:$T$676,$S13,'KK Penjaminan Kualitas'!$E$6:$E$676,"D")/SUMPRODUCT(('KK Penjaminan Kualitas'!$T$6:$T$676=$S13)*('KK Penjaminan Kualitas'!$E$6:$E$676="D")*ISNUMBER('KK Penjaminan Kualitas'!$R$6:$R$676)),"") | L13: =IFERROR(SUMIFS('KK Penjaminan Kualitas'!$R$6:$R$676,'KK Penjaminan Kualitas'!$T$6:$T$676,$S13,'KK Penjaminan Kualitas'!$E$6:$E$676,"C")/SUMPRODUCT(('KK Penjaminan Kualitas'!$T$6:$T$676=$S13)*('KK Penjaminan Kualitas'!$E$6:$E$676="C")*ISNUMBER('KK Penjaminan Kualitas'!$R$6:$R$676)),"") | M13: =IFERROR(SUMIFS('KK Penjaminan Kualitas'!$R$6:$R$676,'KK Penjaminan Kualitas'!$T$6:$T$676,$S13,'KK Penjaminan Kualitas'!$E$6:$E$676,"B")/SUMPRODUCT(('KK Penjaminan Kualitas'!$T$6:$T$676=$S13)*('KK Penjaminan Kualitas'!$E$6:$E$676="B")*ISNUMBER('KK Penjaminan Kualitas'!$R$6:$R$676)),"") | N13: =IFERROR(SUMIFS('KK Penjaminan Kualitas'!$R$6:$R$676,'KK Penjaminan Kualitas'!$T$6:$T$676,$S13,'KK Penjaminan Kualitas'!$E$6:$E$676,"A")/SUMPRODUCT(('KK Penjaminan Kualitas'!$T$6:$T$676=$S13)*('KK Penjaminan Kualitas'!$E$6:$E$676="A")*ISNUMBER('KK Penjaminan Kualitas'!$R$6:$R$676)),"") | O13: =IF(H13=0,"",SUMIFS('KK Penjaminan Kualitas'!$R$6:$R$676,'KK Penjaminan Kualitas'!$T$6:$T$676,$S13)/H13) | P13: =IF(Q13="","",IF(Q13=0,"< E",MID("EDCBA",Q13,1))) | Q13: =IF(H13=0,"",IF(NOT(AND(ISNUMBER(J13),J13>=Petunjuk!$C$14)),0,IF(NOT(AND(ISNUMBER(K13),K13>=Petunjuk!$C$14)),1,IF(NOT(AND(ISNUMBER(L13),L13>=Petunjuk!$C$14)),2,IF(NOT(AND(ISNUMBER(M13),M13>=Petunjuk!$C$14)),3,IF(NOT(AND(ISNUMBER(N13),N13>=Petunjuk!$C$14)),4,5)))))) | R13: =IF(Q13="","Belum dinilai",IF(Q13=5,"Seluruh grade terpenuhi","Lengkapi evidence Grade "&MID("EDCBA",Q13+1,1)&IF(I13>0," ("&I13&" item belum dinilai)",""))) | S13: 1.6-1
A14: 10 | B14: 1.6 | C14: Penyusunan dan Penerapan Kebijakan yang Sehat tentang Pembinaan SDM | D14: 2 | E14: =IFERROR(INDEX(FILTER('KK Penjaminan Kualitas'!$D$6:$D$676,'KK Penjaminan Kualitas'!$A$6:$A$676=B14,'KK Penjaminan Kualitas'!$C$6:$C$676=D14),1),"") | F14: =COUNTIFS('KK Penjaminan Kualitas'!$T$6:$T$676,$S14,'KK Penjaminan Kualitas'!$J$6:$J$676,"<>") | G14: =COUNTIFS('KK Penjaminan Kualitas'!$T$6:$T$676,$S14,'KK Penjaminan Kualitas'!$L$6:$L$676,"N/A") | H14: =SUMPRODUCT(('KK Penjaminan Kualitas'!$T$6:$T$676=$S14)*ISNUMBER('KK Penjaminan Kualitas'!$R$6:$R$676)) | I14: =F14-G14-H14 | J14: =IFERROR(SUMIFS('KK Penjaminan Kualitas'!$R$6:$R$676,'KK Penjaminan Kualitas'!$T$6:$T$676,$S14,'KK Penjaminan Kualitas'!$E$6:$E$676,"E")/SUMPRODUCT(('KK Penjaminan Kualitas'!$T$6:$T$676=$S14)*('KK Penjaminan Kualitas'!$E$6:$E$676="E")*ISNUMBER('KK Penjaminan Kualitas'!$R$6:$R$676)),"") | K14: =IFERROR(SUMIFS('KK Penjaminan Kualitas'!$R$6:$R$676,'KK Penjaminan Kualitas'!$T$6:$T$676,$S14,'KK Penjaminan Kualitas'!$E$6:$E$676,"D")/SUMPRODUCT(('KK Penjaminan Kualitas'!$T$6:$T$676=$S14)*('KK Penjaminan Kualitas'!$E$6:$E$676="D")*ISNUMBER('KK Penjaminan Kualitas'!$R$6:$R$676)),"") | L14: =IFERROR(SUMIFS('KK Penjaminan Kualitas'!$R$6:$R$676,'KK Penjaminan Kualitas'!$T$6:$T$676,$S14,'KK Penjaminan Kualitas'!$E$6:$E$676,"C")/SUMPRODUCT(('KK Penjaminan Kualitas'!$T$6:$T$676=$S14)*('KK Penjaminan Kualitas'!$E$6:$E$676="C")*ISNUMBER('KK Penjaminan Kualitas'!$R$6:$R$676)),"") | M14: =IFERROR(SUMIFS('KK Penjaminan Kualitas'!$R$6:$R$676,'KK Penjaminan Kualitas'!$T$6:$T$676,$S14,'KK Penjaminan Kualitas'!$E$6:$E$676,"B")/SUMPRODUCT(('KK Penjaminan Kualitas'!$T$6:$T$676=$S14)*('KK Penjaminan Kualitas'!$E$6:$E$676="B")*ISNUMBER('KK Penjaminan Kualitas'!$R$6:$R$676)),"") | N14: =IFERROR(SUMIFS('KK Penjaminan Kualitas'!$R$6:$R$676,'KK Penjaminan Kualitas'!$T$6:$T$676,$S14,'KK Penjaminan Kualitas'!$E$6:$E$676,"A")/SUMPRODUCT(('KK Penjaminan Kualitas'!$T$6:$T$676=$S14)*('KK Penjaminan Kualitas'!$E$6:$E$676="A")*ISNUMBER('KK Penjaminan Kualitas'!$R$6:$R$676)),"") | O14: =IF(H14=0,"",SUMIFS('KK Penjaminan Kualitas'!$R$6:$R$676,'KK Penjaminan Kualitas'!$T$6:$T$676,$S14)/H14) | P14: =IF(Q14="","",IF(Q14=0,"< E",MID("EDCBA",Q14,1))) | Q14: =IF(H14=0,"",IF(NOT(AND(ISNUMBER(J14),J14>=Petunjuk!$C$14)),0,IF(NOT(AND(ISNUMBER(K14),K14>=Petunjuk!$C$14)),1,IF(NOT(AND(ISNUMBER(L14),L14>=Petunjuk!$C$14)),2,IF(NOT(AND(ISNUMBER(M14),M14>=Petunjuk!$C$14)),3,IF(NOT(AND(ISNUMBER(N14),N14>=Petunjuk!$C$14)),4,5)))))) | R14: =IF(Q14="","Belum dinilai",IF(Q14=5,"Seluruh grade terpenuhi","Lengkapi evidence Grade "&MID("EDCBA",Q14+1,1)&IF(I14>0," ("&I14&" item belum dinilai)",""))) | S14: 1.6-2
A15: 11 | B15: 1.6 | C15: Penyusunan dan Penerapan Kebijakan yang Sehat tentang Pembinaan SDM | D15: 3 | E15: =IFERROR(INDEX(FILTER('KK Penjaminan Kualitas'!$D$6:$D$676,'KK Penjaminan Kualitas'!$A$6:$A$676=B15,'KK Penjaminan Kualitas'!$C$6:$C$676=D15),1),"") | F15: =COUNTIFS('KK Penjaminan Kualitas'!$T$6:$T$676,$S15,'KK Penjaminan Kualitas'!$J$6:$J$676,"<>") | G15: =COUNTIFS('KK Penjaminan Kualitas'!$T$6:$T$676,$S15,'KK Penjaminan Kualitas'!$L$6:$L$676,"N/A") | H15: =SUMPRODUCT(('KK Penjaminan Kualitas'!$T$6:$T$676=$S15)*ISNUMBER('KK Penjaminan Kualitas'!$R$6:$R$676)) | I15: =F15-G15-H15 | J15: =IFERROR(SUMIFS('KK Penjaminan Kualitas'!$R$6:$R$676,'KK Penjaminan Kualitas'!$T$6:$T$676,$S15,'KK Penjaminan Kualitas'!$E$6:$E$676,"E")/SUMPRODUCT(('KK Penjaminan Kualitas'!$T$6:$T$676=$S15)*('KK Penjaminan Kualitas'!$E$6:$E$676="E")*ISNUMBER('KK Penjaminan Kualitas'!$R$6:$R$676)),"") | K15: =IFERROR(SUMIFS('KK Penjaminan Kualitas'!$R$6:$R$676,'KK Penjaminan Kualitas'!$T$6:$T$676,$S15,'KK Penjaminan Kualitas'!$E$6:$E$676,"D")/SUMPRODUCT(('KK Penjaminan Kualitas'!$T$6:$T$676=$S15)*('KK Penjaminan Kualitas'!$E$6:$E$676="D")*ISNUMBER('KK Penjaminan Kualitas'!$R$6:$R$676)),"") | L15: =IFERROR(SUMIFS('KK Penjaminan Kualitas'!$R$6:$R$676,'KK Penjaminan Kualitas'!$T$6:$T$676,$S15,'KK Penjaminan Kualitas'!$E$6:$E$676,"C")/SUMPRODUCT(('KK Penjaminan Kualitas'!$T$6:$T$676=$S15)*('KK Penjaminan Kualitas'!$E$6:$E$676="C")*ISNUMBER('KK Penjaminan Kualitas'!$R$6:$R$676)),"") | M15: =IFERROR(SUMIFS('KK Penjaminan Kualitas'!$R$6:$R$676,'KK Penjaminan Kualitas'!$T$6:$T$676,$S15,'KK Penjaminan Kualitas'!$E$6:$E$676,"B")/SUMPRODUCT(('KK Penjaminan Kualitas'!$T$6:$T$676=$S15)*('KK Penjaminan Kualitas'!$E$6:$E$676="B")*ISNUMBER('KK Penjaminan Kualitas'!$R$6:$R$676)),"") | N15: =IFERROR(SUMIFS('KK Penjaminan Kualitas'!$R$6:$R$676,'KK Penjaminan Kualitas'!$T$6:$T$676,$S15,'KK Penjaminan Kualitas'!$E$6:$E$676,"A")/SUMPRODUCT(('KK Penjaminan Kualitas'!$T$6:$T$676=$S15)*('KK Penjaminan Kualitas'!$E$6:$E$676="A")*ISNUMBER('KK Penjaminan Kualitas'!$R$6:$R$676)),"") | O15: =IF(H15=0,"",SUMIFS('KK Penjaminan Kualitas'!$R$6:$R$676,'KK Penjaminan Kualitas'!$T$6:$T$676,$S15)/H15) | P15: =IF(Q15="","",IF(Q15=0,"< E",MID("EDCBA",Q15,1))) | Q15: =IF(H15=0,"",IF(NOT(AND(ISNUMBER(J15),J15>=Petunjuk!$C$14)),0,IF(NOT(AND(ISNUMBER(K15),K15>=Petunjuk!$C$14)),1,IF(NOT(AND(ISNUMBER(L15),L15>=Petunjuk!$C$14)),2,IF(NOT(AND(ISNUMBER(M15),M15>=Petunjuk!$C$14)),3,IF(NOT(AND(ISNUMBER(N15),N15>=Petunjuk!$C$14)),4,5)))))) | R15: =IF(Q15="","Belum dinilai",IF(Q15=5,"Seluruh grade terpenuhi","Lengkapi evidence Grade "&MID("EDCBA",Q15+1,1)&IF(I15>0," ("&I15&" item belum dinilai)",""))) | S15: 1.6-3
A16: 12 | B16: 1.7 | C16: Perwujudan Peran APIP yang Efektf | D16: 1 | E16: =IFERROR(INDEX(FILTER('KK Penjaminan Kualitas'!$D$6:$D$676,'KK Penjaminan Kualitas'!$A$6:$A$676=B16,'KK Penjaminan Kualitas'!$C$6:$C$676=D16),1),"") | F16: =COUNTIFS('KK Penjaminan Kualitas'!$T$6:$T$676,$S16,'KK Penjaminan Kualitas'!$J$6:$J$676,"<>") | G16: =COUNTIFS('KK Penjaminan Kualitas'!$T$6:$T$676,$S16,'KK Penjaminan Kualitas'!$L$6:$L$676,"N/A") | H16: =SUMPRODUCT(('KK Penjaminan Kualitas'!$T$6:$T$676=$S16)*ISNUMBER('KK Penjaminan Kualitas'!$R$6:$R$676)) | I16: =F16-G16-H16 | J16: =IFERROR(SUMIFS('KK Penjaminan Kualitas'!$R$6:$R$676,'KK Penjaminan Kualitas'!$T$6:$T$676,$S16,'KK Penjaminan Kualitas'!$E$6:$E$676,"E")/SUMPRODUCT(('KK Penjaminan Kualitas'!$T$6:$T$676=$S16)*('KK Penjaminan Kualitas'!$E$6:$E$676="E")*ISNUMBER('KK Penjaminan Kualitas'!$R$6:$R$676)),"") | K16: =IFERROR(SUMIFS('KK Penjaminan Kualitas'!$R$6:$R$676,'KK Penjaminan Kualitas'!$T$6:$T$676,$S16,'KK Penjaminan Kualitas'!$E$6:$E$676,"D")/SUMPRODUCT(('KK Penjaminan Kualitas'!$T$6:$T$676=$S16)*('KK Penjaminan Kualitas'!$E$6:$E$676="D")*ISNUMBER('KK Penjaminan Kualitas'!$R$6:$R$676)),"") | L16: =IFERROR(SUMIFS('KK Penjaminan Kualitas'!$R$6:$R$676,'KK Penjaminan Kualitas'!$T$6:$T$676,$S16,'KK Penjaminan Kualitas'!$E$6:$E$676,"C")/SUMPRODUCT(('KK Penjaminan Kualitas'!$T$6:$T$676=$S16)*('KK Penjaminan Kualitas'!$E$6:$E$676="C")*ISNUMBER('KK Penjaminan Kualitas'!$R$6:$R$676)),"") | M16: =IFERROR(SUMIFS('KK Penjaminan Kualitas'!$R$6:$R$676,'KK Penjaminan Kualitas'!$T$6:$T$676,$S16,'KK Penjaminan Kualitas'!$E$6:$E$676,"B")/SUMPRODUCT(('KK Penjaminan Kualitas'!$T$6:$T$676=$S16)*('KK Penjaminan Kualitas'!$E$6:$E$676="B")*ISNUMBER('KK Penjaminan Kualitas'!$R$6:$R$676)),"") | N16: =IFERROR(SUMIFS('KK Penjaminan Kualitas'!$R$6:$R$676,'KK Penjaminan Kualitas'!$T$6:$T$676,$S16,'KK Penjaminan Kualitas'!$E$6:$E$676,"A")/SUMPRODUCT(('KK Penjaminan Kualitas'!$T$6:$T$676=$S16)*('KK Penjaminan Kualitas'!$E$6:$E$676="A")*ISNUMBER('KK Penjaminan Kualitas'!$R$6:$R$676)),"") | O16: =IF(H16=0,"",SUMIFS('KK Penjaminan Kualitas'!$R$6:$R$676,'KK Penjaminan Kualitas'!$T$6:$T$676,$S16)/H16) | P16: =IF(Q16="","",IF(Q16=0,"< E",MID("EDCBA",Q16,1))) | Q16: =IF(H16=0,"",IF(NOT(AND(ISNUMBER(J16),J16>=Petunjuk!$C$14)),0,IF(NOT(AND(ISNUMBER(K16),K16>=Petunjuk!$C$14)),1,IF(NOT(AND(ISNUMBER(L16),L16>=Petunjuk!$C$14)),2,IF(NOT(AND(ISNUMBER(M16),M16>=Petunjuk!$C$14)),3,IF(NOT(AND(ISNUMBER(N16),N16>=Petunjuk!$C$14)),4,5)))))) | R16: =IF(Q16="","Belum dinilai",IF(Q16=5,"Seluruh grade terpenuhi","Lengkapi evidence Grade "&MID("EDCBA",Q16+1,1)&IF(I16>0," ("&I16&" item belum dinilai)",""))) | S16: 1.7-1
... A47: 43 | B47: 5.2 | C47: Evaluasi Terpisah | D47: 2 | E47: =IFERROR(INDEX(FILTER('KK Penjaminan Kualitas'!$D$6:$D$676,'KK Penjaminan Kualitas'!$A$6:$A$676=B47,'KK Penjaminan Kualitas'!$C$6:$C$676=D47),1),"") | F47: =COUNTIFS('KK Penjaminan Kualitas'!$T$6:$T$676,$S47,'KK Penjaminan Kualitas'!$J$6:$J$676,"<>") | G47: =COUNTIFS('KK Penjaminan Kualitas'!$T$6:$T$676,$S47,'KK Penjaminan Kualitas'!$L$6:$L$676,"N/A") | H47: =SUMPRODUCT(('KK Penjaminan Kualitas'!$T$6:$T$676=$S47)*ISNUMBER('KK Penjaminan Kualitas'!$R$6:$R$676)) | I47: =F47-G47-H47 | J47: =IFERROR(SUMIFS('KK Penjaminan Kualitas'!$R$6:$R$676,'KK Penjaminan Kualitas'!$T$6:$T$676,$S47,'KK Penjaminan Kualitas'!$E$6:$E$676,"E")/SUMPRODUCT(('KK Penjaminan Kualitas'!$T$6:$T$676=$S47)*('KK Penjaminan Kualitas'!$E$6:$E$676="E")*ISNUMBER('KK Penjaminan Kualitas'!$R$6:$R$676)),"") | K47: =IFERROR(SUMIFS('KK Penjaminan Kualitas'!$R$6:$R$676,'KK Penjaminan Kualitas'!$T$6:$T$676,$S47,'KK Penjaminan Kualitas'!$E$6:$E$676,"D")/SUMPRODUCT(('KK Penjaminan Kualitas'!$T$6:$T$676=$S47)*('KK Penjaminan Kualitas'!$E$6:$E$676="D")*ISNUMBER('KK Penjaminan Kualitas'!$R$6:$R$676)),"") | L47: =IFERROR(SUMIFS('KK Penjaminan Kualitas'!$R$6:$R$676,'KK Penjaminan Kualitas'!$T$6:$T$676,$S47,'KK Penjaminan Kualitas'!$E$6:$E$676,"C")/SUMPRODUCT(('KK Penjaminan Kualitas'!$T$6:$T$676=$S47)*('KK Penjaminan Kualitas'!$E$6:$E$676="C")*ISNUMBER('KK Penjaminan Kualitas'!$R$6:$R$676)),"") | M47: =IFERROR(SUMIFS('KK Penjaminan Kualitas'!$R$6:$R$676,'KK Penjaminan Kualitas'!$T$6:$T$676,$S47,'KK Penjaminan Kualitas'!$E$6:$E$676,"B")/SUMPRODUCT(('KK Penjaminan Kualitas'!$T$6:$T$676=$S47)*('KK Penjaminan Kualitas'!$E$6:$E$676="B")*ISNUMBER('KK Penjaminan Kualitas'!$R$6:$R$676)),"") | N47: =IFERROR(SUMIFS('KK Penjaminan Kualitas'!$R$6:$R$676,'KK Penjaminan Kualitas'!$T$6:$T$676,$S47,'KK Penjaminan Kualitas'!$E$6:$E$676,"A")/SUMPRODUCT(('KK Penjaminan Kualitas'!$T$6:$T$676=$S47)*('KK Penjaminan Kualitas'!$E$6:$E$676="A")*ISNUMBER('KK Penjaminan Kualitas'!$R$6:$R$676)),"") | O47: =IF(H47=0,"",SUMIFS('KK Penjaminan Kualitas'!$R$6:$R$676,'KK Penjaminan Kualitas'!$T$6:$T$676,$S47)/H47) | P47: =IF(Q47="","",IF(Q47=0,"< E",MID("EDCBA",Q47,1))) | Q47: =IF(H47=0,"",IF(NOT(AND(ISNUMBER(J47),J47>=Petunjuk!$C$14)),0,IF(NOT(AND(ISNUMBER(K47),K47>=Petunjuk!$C$14)),1,IF(NOT(AND(ISNUMBER(L47),L47>=Petunjuk!$C$14)),2,IF(NOT(AND(ISNUMBER(M47),M47>=Petunjuk!$C$14)),3,IF(NOT(AND(ISNUMBER(N47),N47>=Petunjuk!$C$14)),4,5)))))) | R47: =IF(Q47="","Belum dinilai",IF(Q47=5,"Seluruh grade terpenuhi","Lengkapi evidence Grade "&MID("EDCBA",Q47+1,1)&IF(I47>0," ("&I47&" item belum dinilai)",""))) | S47: 5.2-2
E48: =IFERROR(INDEX(FILTER('KK Penjaminan Kualitas'!$D$6:$D$676,'KK Penjaminan Kualitas'!$A$6:$A$676=B48,'KK Penjaminan Kualitas'!$C$6:$C$676=D48),1),"") | F48: =SUM(F5:F47) | G48: =SUM(G5:G47) | H48: =SUM(H5:H47) | I48: =SUM(I5:I47) | J48: =IFERROR(SUMIFS('KK Penjaminan Kualitas'!$R$6:$R$676,'KK Penjaminan Kualitas'!$E$6:$E$676,"E")/SUMPRODUCT(('KK Penjaminan Kualitas'!$E$6:$E$676="E")*ISNUMBER('KK Penjaminan Kualitas'!$R$6:$R$676)),"") | K48: =IFERROR(SUMIFS('KK Penjaminan Kualitas'!$R$6:$R$676,'KK Penjaminan Kualitas'!$E$6:$E$676,"D")/SUMPRODUCT(('KK Penjaminan Kualitas'!$E$6:$E$676="D")*ISNUMBER('KK Penjaminan Kualitas'!$R$6:$R$676)),"") | L48: =IFERROR(SUMIFS('KK Penjaminan Kualitas'!$R$6:$R$676,'KK Penjaminan Kualitas'!$E$6:$E$676,"C")/SUMPRODUCT(('KK Penjaminan Kualitas'!$E$6:$E$676="C")*ISNUMBER('KK Penjaminan Kualitas'!$R$6:$R$676)),"") | M48: =IFERROR(SUMIFS('KK Penjaminan Kualitas'!$R$6:$R$676,'KK Penjaminan Kualitas'!$E$6:$E$676,"B")/SUMPRODUCT(('KK Penjaminan Kualitas'!$E$6:$E$676="B")*ISNUMBER('KK Penjaminan Kualitas'!$R$6:$R$676)),"") | N48: =IFERROR(SUMIFS('KK Penjaminan Kualitas'!$R$6:$R$676,'KK Penjaminan Kualitas'!$E$6:$E$676,"A")/SUMPRODUCT(('KK Penjaminan Kualitas'!$E$6:$E$676="A")*ISNUMBER('KK Penjaminan Kualitas'!$R$6:$R$676)),"") | O48: =IF(H48=0,"",SUM('KK Penjaminan Kualitas'!$R$6:$R$676)/H48)
E49: =IFERROR(INDEX(FILTER('KK Penjaminan Kualitas'!$D$6:$D$676,'KK Penjaminan Kualitas'!$A$6:$A$676=B49,'KK Penjaminan Kualitas'!$C$6:$C$676=D49),1),"") | O49: =COUNTIF(Q5:Q47,">=3")&" dari "&COUNTA(D5:D47)
E50: =IFERROR(INDEX(FILTER('KK Penjaminan Kualitas'!$D$6:$D$676,'KK Penjaminan Kualitas'!$A$6:$A$676=B50,'KK Penjaminan Kualitas'!$C$6:$C$676=D50),1),"")
B51: Keterangan: % Grade = Σ nilai item ÷ item dinilai (di luar N/A) pada grade tersebut. Grade Indikatif dihitung berjenjang dari E ke A dengan ambang batas pada Petunjuk!C14. Sel kosong = belum ada item yang dinilai. | E51: =IFERROR(INDEX(FILTER('KK Penjaminan Kualitas'!$D$6:$D$676,'KK Penjaminan Kualitas'!$A$6:$A$676=B51,'KK Penjaminan Kualitas'!$C$6:$C$676=D51),1),"")

Sheet Rekap Unsur
A1: REKAPITULASI HASIL PENJAMINAN KUALITAS / QUALITY ASSURANCE APIP PER UNSUR DAN SUBUNSUR
A2: ="OPD: "&IF(Petunjuk!$C$5="","..........",Petunjuk!$C$5)&" | Tahun Penilaian: "&IF(Petunjuk!$C$6="","....",Petunjuk!$C$6)
A4: Kode | B4: Unsur / Subunsur | C4: Jml Parameter | D4: Jml Item Evidence | E4: Item N/A | F4: Item Dinilai | G4: Σ Nilai | H4: % Pemenuhan Dokumen | I4: Parameter ≥ Level 3 | J4: Kategori | L4: KPI QA APIP
A5: 1 | B5: Unsur 1. Lingkungan Pengendalian | C5: =COUNTIF('Rekap Parameter'!$B$5:$B$47,"1.*") | D5: =SUMIF('Rekap Parameter'!$B$5:$B$47,"1.*",'Rekap Parameter'!$F$5:$F$47) | E5: =SUMIF('Rekap Parameter'!$B$5:$B$47,"1.*",'Rekap Parameter'!$G$5:$G$47) | F5: =SUMIF('Rekap Parameter'!$B$5:$B$47,"1.*",'Rekap Parameter'!$H$5:$H$47) | G5: =SUMIF('KK Penjaminan Kualitas'!$T$6:$T$676,"1.*",'KK Penjaminan Kualitas'!$R$6:$R$676) | H5: =IF(F5=0,"",G5/F5) | I5: =COUNTIFS('Rekap Parameter'!$B$5:$B$47,"1.*",'Rekap Parameter'!$Q$5:$Q$47,">=3") | J5: =IF(H5="","Belum dinilai",IF(H5>=0.8,"Tinggi",IF(H5>=0.6,"Cukup",IF(H5>=0.4,"Kurang","Rendah")))) | L5: Persentase Hasil QA APIP | M5: =IFERROR(SUM('KK Penjaminan Kualitas'!$R$6:$R$676)/COUNT('KK Penjaminan Kualitas'!$R$6:$R$676),"")
